<?xml version="1.0"?>
<robot name="slambotSonic">
  <link name="base_link">
    <visual>
     <geometry>
        <box size="0.9 .45 .25"/>
      </geometry>
    </visual>
  </link>

  <link name="ultrasound">
    <visual>
      <geometry>
        <box size="0.08 0.08 0.16"/>
      </geometry>
      <origin rpy="0 0 0" xyz="0 0 -0.01"/>
      <material name="green">
        <color rgba="0 1 0 0.8"/>
       </material>
    </visual>
  </link>

  <joint name="base_to_ultrasound" type="fixed">
    <parent link="base_link"/>
    <child link="ultrasound"/>
    <origin xyz="0.45 0 .14"/>
  </joint>

  <link name="left_front_wheel">
    <visual>
      <geometry>
        <cylinder length=".04" radius="0.2"/>
      </geometry>
      <origin xyz="0 0 0.024"/>
      <material name="black"/>
    </visual>
  </link>

  <joint name="left_front_wheel_joint" type="fixed">
    <parent link="base_link"/>
    <child link="left_front_wheel"/>
    <origin rpy="0 1.57075 1.57075" xyz="0 0.225 -0.085"/>
  </joint>

  <link name="right_front_wheel">
    <visual>
      <geometry>
        <cylinder length=".04" radius="0.2"/>
      </geometry>
      <origin xyz="0 0 -0.024"/>
      <material name="black"/>
    </visual>
  </link>

  <joint name="right_front_wheel_joint" type="fixed">
    <parent link="base_link"/>
    <child link="right_front_wheel"/>
    <origin rpy="0 1.57075 1.57075" xyz="0 -0.225 -0.085"/>
  </joint>


  <link name="link2" >
    <visual>
      <geometry>
        <cylinder length="1.56" radius="0.2"/>
      </geometry>
      <origin xyz="0 0 0.79"/>
      <material name="black"/>
    </visual>
  </link>

  <joint name="joint1" type="continuous">
    <parent link="base_link"/>
    <child link="link2"/>
    <origin xyz="0 0.67 1.58" rpy="0 0 0" /> 
    <!--axis xyz="0 0 1" /-->
  </joint>

  <link name="link3" />


  <joint name="joint2" type="continuous">
    <parent link="link2"/>
    <child link="link3"/>
    <origin xyz="0.452 3.61 0.39" rpy="0 1.57 0" /> 
    <!--axis xyz="0 0 1" /-->
  </joint>

  <link name="link4" />


  <joint name="joint3" type="continuous">
    <parent link="link3"/>
    <child link="link4"/>
    <origin xyz="0.4 0 0" rpy="0 -1.57 0" /> 
    <axis xyz="0 0 1" />
  </joint>
  <link name="link5" />



  <joint name="joint4" type="continuous">
    <parent link="link4"/>
    <child link="link5"/>
    <origin xyz="2.19 0 0" rpy="0 1.57 0" /> 
    <axis xyz="0 0 1" />
  </joint>
  <link name="link6" />

  <joint name="joint5" type="continuous">
    <parent link="link5"/>
    <child link="link6"/>
    <origin xyz="0.6 0 0" rpy="0 0 0" /> 
    <axis xyz="0 0 1" />
  </joint>


</robot>


